Workbook
Name CList: 'P&L Other Details'!$XFD$2:$XFD$251
Name SList: 'P&L Other Details'!$XFC$2:$XFC$42

Sheet Balance Sheet
A1: A | B1: SOURCES OF FUNDS
B2: 1 | C2: Partners' / Members' fund
C3: a | D3: Partners' / members' capital | J3: a
C4: b | D4: Reserves and Surplus
D5: i | E5: Revaluation Reserve | H5: Bi
D6: ii | E6: Capital Reserve | H6: bii
D7: iii | E7: Statutory Reserve | H7: biii
D8: iv | E8: Any other Reserve | H8: biv
D9: v | E9: Credit balance of Profit and loss account | H9: bv
D10: vi | E10: Total (bi+bii+biii+biv+bv) | J10: bvi | K10: =SUM(I5:I9) -> 0
C11: c | D11: Total partners' / members' fund (a+bvi) | J11: 1c | K11: =SUM(K3,K10) -> 0
B12: 2 | C12: Loan funds
C13: a | D13: Secured loans
D14: i | E14: Foreign Currency Loans | H14: ai
D15: ii | E15: Rupee Loans
E16: A | F16: From Banks | H16: iiA
E17: B | F17: From others | H17: iiB
E18: C | F18: Total (iiA+iiB) | H18: iiC | I18: =SUM(I16:I17) -> 0
D19: iii | E19: Total secured loans (ai+aiiC) | J19: aiii | K19: =SUM(I14,I18) -> 0
C20: b | D20: Unsecured loans (including deposits)
D21: i | E21: Foreign Currency Loans | H21: bi
D22: ii | E22: Rupee Loans
E23: A | F23: From Banks | H23: iiA
E24: B | F24: From persons specified in section 40A(2)(b) of the I.T. Act | H24: iiB
E25: C | F25: From others | H25: iiC
E26: D | F26: Total Rupee Loans (iiA+iiB+iiC) | H26: iiD | I26: =SUM(I23:I25) -> 0
D27: iii | E27: Total unsecured loans (bi+biiD) | J27: biii | K27: =SUM(I21,I26) -> 0
C28: C | D28: Total Loan Funds (aiii+biii) | J28: 2c | K28: =SUM(K19,K27) -> 0
B29: 3 | C29: Deferred tax liability | J29: 3
B30: 4 | C30: Advances
C31: i | D31: From persons specified in section 40A(2)(b) of I.T. Act | H31: i
C32: ii | D32: From others | H32: ii
C33: iii | D33: Total Advances (i + ii) | J33: 4iii | K33: =SUM(I31:I32) -> 0
B34: 5 | C34: Sources of funds (1c+2c+3+4iii) | J34: 5 | K34: =SUM(K11,K28,K29,K33) -> 0
A35: B | B35: APPLICATION OF FUNDS
B36: 1 | C36: Fixed assets
C37: a | D37: Gross: Block | H37: 1a
C38: b | D38: Depreciation | H38: 1b
C39: c | D39: Net Block (a-b) | H39: 1c | I39: =I37-I38 -> 0
C40: d | D40: Capital work-in-progress | H40: 1d
...

Sheet Manufacturing Account
A1: I | B1: Opening Inventory
B2: A | C2: i | D2: Opening stock of raw-material | H2: i
C3: ii | D3: Opening stock of Work in progress | H3: ii
C4: iii | D4: Total (i + ii) | J4: Aiii | K4: =SUM(I2:I3) -> 0
B5: B | C5: Purchases (net of refunds and duty or tax, if any) | J5: B
B6: C | C6: Direct wages | J6: C
B7: D | C7: Direct expenses ( Di + Dii + Diii ) | J7: D | K7: =SUM(I8:I10) -> 0
C8: i | D8: Carriage inward | H8: i
C9: ii | D9: Power and fuel | H9: ii
C10: iii | D10: Other direct expenses | H10: iii
B11: E | C11: Factory Overheads
C12: i | D12: Indirect wages | H12: i
C13: ii | D13: Factory rent and rates | H13: ii
C14: iii | D14: Factory Insurance | H14: iii
C15: iv | D15: Factory fuel and power | H15: iv
C16: v | D16: Factory general expenses | H16: v
C17: vi | D17: Depreciation of factory machinery | H17: vi
C18: Total ( i + ii + iii + iv + v + vi ) | J18: Evii | K18: =SUM(I12:I17) -> 0
B19: F | C19: Total of Debits to Manufacturing Account ( Aiii + B + C + D + Evii ) | J19: 1F | K19: =SUM(K4:K7,K18) -> 0
A20: 2 | B20: Closing Stock
B21: i | C21: Raw material | H21: 2i
B22: ii | C22: Work-in-progress | H22: 2ii
B23: Total ( 2i + 2ii ) | J23: 2 | K23: =SUM(I21:I22) -> 0
A24: 3 | B24: Cost of Goods Produced – transferred to Trading Account ( 1F – 2 ) | J24: 3 | K24: =K19-K23 -> 0

Sheet Trading Account
A1: CREDITS TO TRADING ACCOUNT
A2: 4 | B2: Revenue from operations
B3: A | C3: Sales/Gross receipts of business (net of returns and refunds and duty or tax, if any)
C4: i | D4: Sale of goods | H4: i
C5: ii | D5: Sale of services | H5: ii
C6: iii | D6: Other operating revenues (specify nature and amount) | H6: iii | I6: =SUM('Trading Other Details'!B3:B50) -> 0
C7: iv | D7: Total ( i + ii + iiic ) | J7: Aiv | K7: =SUM(I4:I6) -> 0
B8: B | C8: Gross receipts from Profession | J8: B
B9: C | C9: Duties, taxes and cess, received or receivable, in respect of goods and services sold or supplied
C10: i | D10: Union Excise duties | H10: i
C11: ii | D11: Service tax | H11: ii
C12: iii | D12: VAT/Sales tax | H12: iii
C13: iv | D13: Central Goods & Service Tax (CGST) | H13: iv
C14: v | D14: State Goods & Services Tax (SGST) | H14: v
C15: vi | D15: Integrated Goods & Services Tax (IGST) | H15: vi
C16: vii | D16: Union Territory Goods & Services Tax (UTGST) | H16: vii
C17: viii | D17: Any other duty, tax and cess | H17: viii
C18: ix | D18: Total ( i + ii + iii + iv + v + vi + vii + viii ) | J18: Cix | K18: =SUM(I10:I17) -> 0
B19: D | C19: Total Revenue from operations ( Aiv + B + Cix ) | J19: 4D | K19: =SUM(K7:K8,K18) -> 0
A20: 5 | B20: Closing Stock of Finished Stocks | J20: 5
A21: 6 | B21: Total of credits to Trading Account ( 4D + 5 ) | J21: 6 | K21: =SUM(K19:K20) -> 0
A22: DEBITS TO TRADING ACCOUNT
A23: 7 | B23: Opening Stock of Finished Goods | J23: 7
A24: 8 | B24: Purchases (net of refunds and duty or tax, if any) | J24: 8
A25: 9 | B25: Direct Expenses (9i + 9ii + 9iii) | J25: 9 | K25: =SUM(I26:I28) -> 0
B26: i | C26: Carriage inward | H26: 9i
B27: ii | C27: Power and fuel | H27: 9ii
B28: iii | C28: Other direct expenses (specify nature and amount) | H28: 9iii | I28: =SUM('Trading Other Details'!E3:E50) -> 0
A29: 10 | B29: Duties and taxes, paid or payable, in respect of goods and services purchased
B30: i | C30: Custom duty | H30: 10i
B31: ii | C31: Counter vailing duty | H31: 10ii
B32: iii | C32: Special additional duty | H32: 10iii
B33: iv | C33: Union excise duty | H33: 10iv
B34: v | C34: Service tax | H34: 10v
B35: vi | C35: VAT/Sales tax | H35: 10vi
B36: vii | C36: Central Goods & Service Tax (CGST) | H36: 10vii
B37: viii | C37: State Goods & Services Tax (SGST) | H37: 10viii
B38: ix | C38: Integrated Goods & Services Tax (IGST) | H38: 10ix
B39: x | C39: Union Territory Goods & Services Tax (UTGST) | H39: 10x
B40: xi | C40: Any other tax, paid or payable | H40: 10xi
...

Sheet Trading Other Details
A1: Other operating revenues (specify nature and amount) | D1: Other direct expenses (specify nature and amount)
A2: Particulars | B2: Amount | D2: Particulars | E2: Amount

Sheet Profit and Loss Account
A1: CREDITS TO PROFIT AND LOSS ACCOUNT
A2: 13 | B2: Gross profit transferred from Trading Account | J2: 13 | K2: ='Trading Account'!K43+'Trading Account'!K45+'Trading Account'!K47 -> 0
A3: 14 | B3: Other income
B4: i | C4: Rent | H4: i
B5: ii | C5: Commission | H5: ii
B6: iii | C6: Dividend income | H6: iii
B7: iv | C7: Interest income | H7: iv
B8: v | C8: Profit on sale of fixed assets | H8: v
B9: vi | C9: Profit on sale of investment being securities chargeable to Securities Transaction Tax (STT) | H9: vi
B10: vii | C10: Profit on sale of other investment | H10: vii
B11: viii | C11: Gain (loss) on account of foreign exchange fluctuation u/s 43AA | H11: viii
B12: ix | C12: Profit on conversion of inventory into capital asset u/s 28(via) (Fair Market Value of inventory as on the date of conversion) | H12: ix
B13: x | C13: Agriculture income | H13: x
B14: xi | C14: Any other income (specify nature and amount) | H14: xi | I14: =SUM('P&L Other Details'!B3:B50) -> 0
B15: xii | C15: Total of other income ( i + ii + iii + iv + v + vi + vii + viii + ix + x + xic ) | J15: 14xii | K15: =SUM(I4:I14) -> 0
A16: 15 | B16: Total of credits to profit and loss account (13+14xii) | J16: 15 | K16: =SUM(K2,K15) -> 0
A17: DEBITS TO PROFIT AND LOSS ACCOUNT
A18: 16 | B18: Freight outward | J18: 16
A19: 17 | B19: Consumption of stores and spare parts | J19: 17
A20: 18 | B20: Power and fuel | J20: 18
A21: 19 | B21: Rents | J21: 19
A22: 20 | B22: Repairs to building | J22: 20
A23: 21 | B23: Repairs to machinery | J23: 21
A24: 22 | B24: Compensation to employees
B25: i | C25: Salaries and wages | H25: 22i
B26: ii | C26: Bonus | H26: 22ii
B27: iii | C27: Reimbursement of medical expenses | H27: 22iii
B28: iv | C28: Leave encashment | H28: 22iv
B29: v | C29: Leave travel benefits | H29: 22v
B30: vi | C30: Contribution to approved superannuation fund | H30: 22vi
B31: vii | C31: Contribution to recognised provident fund | H31: 22vii
B32: viii | C32: Contribution to recognised gratuity fund | H32: 22viii
B33: ix | C33: Contribution to any other fund | H33: 22ix
B34: x | C34: Any other benefit to employees in respect of which an expenditure has been incurred | H34: 22x
B35: xi | C35: Total compensation to employees (total of 22i to 22x) | J35: 22xi | K35: =SUM(I25:I34) -> 0
B36: xii | C36: Any compensation amount , included in 22xi, paid to non-residents | H36: xii
A37: 23 | B37: Insurance
B38: i | C38: Medical Insurance | H38: 23i
B39: ii | C39: Life Insurance | H39: 23ii
B40: iii | C40: Keyman's Insurance | H40: 23iii
...

Sheet P&L Other Details
A1: Any other income (specify nature and amount) | D1: Other expenses (Specify amount and nature) | G1: Bad Debt for amount of Rs. 1 lakh or more, where PAN is available | K1: Bad Debt for amount of Rs. 1 lakh or more, where PAN is not available (provide name and complete address) | V1: Others (amounts less than Rs. 1 lakh) | XFC1: STATE | XFD1: COUNTRY
A2: Particulars | B2: Amount | D2: Particulars | E2: Amount | G2: PAN of person | H2: AADHAAR of person | I2: Amount | K2: Name of person | L2: Flat/ Door /Block No. | M2: Name of premises/ building/ village | N2: Road/ Street/ Post office | O2: Area/ Locality | P2: Town/ City/ District | Q2: State | R2: Country | S2: PIN/ZIP Code | T2: Amount | V2: Particulars | W2: Amount | XFC2: ANDAMAN AND NICOBAR ISLANDS | XFD2: AFGHANISTAN
A3: Liabilities written back | XFC3: ANDHRA PRADESH | XFD3: ALAND ISLANDS
XFC4: ARUNACHAL PRADESH | XFD4: ALBANIA
XFC5: ASSAM | XFD5: ALGERIA
XFC6: BIHAR | XFD6: AMERICAN SAMOA
XFC7: CHANDIGARH | XFD7: ANDORRA
XFC8: DADRA & NAGAR HAVELI | XFD8: ANGOLA
XFC9: DAMAN & DIU | XFD9: ANGUILLA
XFC10: DELHI | XFD10: ANTARCTICA
XFC11: GOA | XFD11: ANTIGUA AND BARBUDA
XFC12: GUJARAT | XFD12: ARGENTINA
XFC13: HARYANA | XFD13: ARMENIA
XFC14: HIMACHAL PRADESH | XFD14: ARUBA
XFC15: JAMMU & KASHMIR | XFD15: AUSTRALIA
... XFC42: STATE OUTSIDE INDIA | XFD42: CANADA
XFD43: CAYMAN ISLANDS
XFD44: CENTRAL AFRICAN REPUBLIC
XFD45: CHAD
XFD46: CHILE
XFD47: CHINA
XFD48: CHRISTMAS ISLAND
XFD49: COCOS (KEELING) ISLANDS
XFD50: COLOMBIA
XFD51: COMOROS
XFD52: CONGO
XFD53: CONGO (DEMOCRATIC REPUBLIC OF THE)
XFD54: COOK ISLANDS
... XFD251: OTHERS
